Workbook
Name NativeTimeline_tanggal_pengajuan: #N/A
Name Slicer_non_performing_loan: #N/A

Sheet Data
A1: no_kontrak | B1: tanggal_pengajuan | C1: bulan_pengajuan | D1: nama_debitur | E1: NIK | F1: usia | G1: jenis_kelamin | H1: pekerjaan | I1: penghasilan_bulanan | J1: rasio | K1: kota | L1: provinsi | M1: merk_motor | N1: tipe_motor | O1: segmen_motor | P1: harga_otr | Q1: uang_muka | R1: kategori_dp | S1: persen_dp | T1: tenor_bulan | U1: bunga_flat_pa | V1: cicilan_per_bulan | W1: total_kewajiban | X1: non_performing_loan | Y1: status_pembayaran | Z1: hari_keterlambatan | AA1: jumlah_kali_telat | AB1: kolektibilitas_ojk | AC1: catatan | AD1: Skor_Rasio | AE1: Skor_DP | AF1: Skor_Tenor | AG1: Skor_Telat | AH1: Risk_Score | AI1: Risk_Tier | AJ1: MOB | AK1: MOB_Bucket
A2: KRM00001 | B2: 46176 | C2: =TEXT(B2,"mmmm") -> June | D2: Ayu Susanti | E2: 90842510784931 | F2: 21 | G2: Lakilaki | H2: Karyawan Swasta | I2: 6765000 | J2: =Raw_Data[[#This Row],[cicilan_per_bulan]]/Raw_Data[[#This Row],[penghasilan_bulanan]] -> 0.29600887 | K2: Denpasar | L2: Bali | M2: Honda | N2: Vario 125 | O2: Matic Mid | P2: 24690000 | Q2: 3703000 | R2: =IF(Raw_Data[[#This Row],[persen_dp]]<15%,"Low",IF(Raw_Data[[#This Row],[persen_dp]]>25%,"High","Medium")) -> Medium | S2: 0.15 | T2: 12 | U2: 0.145 | V2: 2002500 | W2: 24030000 | X2: =IF(OR(Raw_Data[[#This Row],[status_pembayaran]]="Macet",Raw_Data[[#This Row],[status_pembayaran]]="Kurang Lancar"),"Non Performing Loan","Performing") -> Performing | Y2: Lancar | Z2: 0 | AA2: 0 | AB2: 1 | AD2: =IF(Raw_Data[[#This Row],[rasio]]<0.2,1,IF(Raw_Data[[#This Row],[rasio]]<0.3,2,IF(Raw_Data[[#This Row],[rasio]]<0.4,3,4))) -> 2 | AE2: =IF(Raw_Data[[#This Row],[kategori_dp]]="High",1,IF(Raw_Data[[#This Row],[kategori_dp]]="Medium",2,3)) -> 2 | AF2: =IF(Raw_Data[[#This Row],[tenor_bulan]]<=24,1,IF(Raw_Data[[#This Row],[tenor_bulan]]<=36,2,IF(Raw_Data[[#This Row],[tenor_bulan]]<=48,3,4))) -> 1 | AG2: =IF(Raw_Data[[#This Row],[jumlah_kali_telat]]=0,0,IF(Raw_Data[[#This Row],[jumlah_kali_telat]]<=2,2,4)) -> 0 | AH2: =Raw_Data[[#This Row],[Skor_Rasio]]+Raw_Data[[#This Row],[Skor_DP]]+Raw_Data[[#This Row],[Skor_Tenor]]+Raw_Data[[#This Row],[Skor_Telat]] -> 5 | AI2: =IF(Raw_Data[[#This Row],[Risk_Score]]<=6,"Low Risk",IF(Raw_Data[[#This Row],[Risk_Score]]<=8,"Medium Risk","High Risk")) -> Low Risk | AJ2: =IFERROR(DATEDIF(Raw_Data[[#This Row],[tanggal_pengajuan]],TODAY(),"m"),"N/A") -> 4 | AK2: =IF(ISNUMBER(Raw_Data[[#This Row],[MOB]]),IF(Raw_Data[[#This Row],[MOB]]<6,"0-5 bulan",IF(Raw_Data[[#This Row],[MOB]]<12,"6-11 bulan",IF(Raw_Data[[#This Row],[MOB]]<24,"12-23 bulan","24+ bulan"))),"N/A") -> 0-5 bulan
A3: KRM00002 | B3: 46103 | C3: =TEXT(B3,"mmmm") -> March | D3: Putri Utami | E3: 96952212822250 | F3: 42 | G3: Perempuan | H3: Wiraswasta | I3: 3632000 | J3: =Raw_Data[[#This Row],[cicilan_per_bulan]]/Raw_Data[[#This Row],[penghasilan_bulanan]] -> 0.11002203 | K3: Palembang | L3: Sumatera Selatan | M3: Yamaha | N3: Mio M3 | O3: Matic Entry | P3: 18533000 | Q3: 4633000 | R3: =IF(Raw_Data[[#This Row],[persen_dp]]<15%,"Low",IF(Raw_Data[[#This Row],[persen_dp]]>25%,"High","Medium")) -> Medium | S3: 0.25 | T3: 60 | U3: 0.145 | V3: 399600 | W3: 23977000 | X3: =IF(OR(Raw_Data[[#This Row],[status_pembayaran]]="Macet",Raw_Data[[#This Row],[status_pembayaran]]="Kurang Lancar"),"Non Performing Loan","Performing") -> Performing | Y3: Lancar | Z3: 0 | AA3: 0 | AB3: 1 | AC3: data kurang | AD3: =IF(Raw_Data[[#This Row],[rasio]]<0.2,1,IF(Raw_Data[[#This Row],[rasio]]<0.3,2,IF(Raw_Data[[#This Row],[rasio]]<0.4,3,4))) -> 1 | AE3: =IF(Raw_Data[[#This Row],[kategori_dp]]="High",1,IF(Raw_Data[[#This Row],[kategori_dp]]="Medium",2,3)) -> 2 | AF3: =IF(Raw_Data[[#This Row],[tenor_bulan]]<=24,1,IF(Raw_Data[[#This Row],[tenor_bulan]]<=36,2,IF(Raw_Data[[#This Row],[tenor_bulan]]<=48,3,4))) -> 4 | AG3: =IF(Raw_Data[[#This Row],[jumlah_kali_telat]]=0,0,IF(Raw_Data[[#This Row],[jumlah_kali_telat]]<=2,2,4)) -> 0 | AH3: =Raw_Data[[#This Row],[Skor_Rasio]]+Raw_Data[[#This Row],[Skor_DP]]+Raw_Data[[#This Row],[Skor_Tenor]]+Raw_Data[[#This Row],[Skor_Telat]] -> 7 | AI3: =IF(Raw_Data[[#This Row],[Risk_Score]]<=6,"Low Risk",IF(Raw_Data[[#This Row],[Risk_Score]]<=8,"Medium Risk","High Risk")) -> Medium Risk | AJ3: =IFERROR(DATEDIF(Raw_Data[[#This Row],[tanggal_pengajuan]],TODAY(),"m"),"N/A") -> 7 | AK3: =IF(ISNUMBER(Raw_Data[[#This Row],[MOB]]),IF(Raw_Data[[#This Row],[MOB]]<6,"0-5 bulan",IF(Raw_Data[[#This Row],[MOB]]<12,"6-11 bulan",IF(Raw_Data[[#This Row],[MOB]]<24,"12-23 bulan","24+ bulan"))),"N/A") -> 6-11 bulan
A4: KRM00003 | B4: 46116 | C4: =TEXT(B4,"mmmm") -> April | D4: Reza Cahyono | E4: 76422502779296 | F4: 52 | G4: Perempuan | H4: Ibu Rumah Tangga | I4: 2118000 | J4: =Raw_Data[[#This Row],[cicilan_per_bulan]]/Raw_Data[[#This Row],[penghasilan_bulanan]] -> 0.2983475 | K4: Pekanbaru | L4: Riau | M4: Yamaha | N4: Lexi LX 155 | O4: Matic Mid | P4: 27476000 | Q4: 5495000 | R4: =IF(Raw_Data[[#This Row],[persen_dp]]<15%,"Low",IF(Raw_Data[[#This Row],[persen_dp]]>25%,"High","Medium")) -> Medium | S4: 0.2 | T4: 60 | U4: 0.145 | V4: 631900 | W4: 37917000 | X4: =IF(OR(Raw_Data[[#This Row],[status_pembayaran]]="Macet",Raw_Data[[#This Row],[status_pembayaran]]="Kurang Lancar"),"Non Performing Loan","Performing") -> Performing | Y4: Lancar | Z4: 0 | AA4: 0 | AB4: 1 | AC4: ok | AD4: =IF(Raw_Data[[#This Row],[rasio]]<0.2,1,IF(Raw_Data[[#This Row],[rasio]]<0.3,2,IF(Raw_Data[[#This Row],[rasio]]<0.4,3,4))) -> 2 | AE4: =IF(Raw_Data[[#This Row],[kategori_dp]]="High",1,IF(Raw_Data[[#This Row],[kategori_dp]]="Medium",2,3)) -> 2 | AF4: =IF(Raw_Data[[#This Row],[tenor_bulan]]<=24,1,IF(Raw_Data[[#This Row],[tenor_bulan]]<=36,2,IF(Raw_Data[[#This Row],[tenor_bulan]]<=48,3,4))) -> 4 | AG4: =IF(Raw_Data[[#This Row],[jumlah_kali_telat]]=0,0,IF(Raw_Data[[#This Row],[jumlah_kali_telat]]<=2,2,4)) -> 0 | AH4: =Raw_Data[[#This Row],[Skor_Rasio]]+Raw_Data[[#This Row],[Skor_DP]]+Raw_Data[[#This Row],[Skor_Tenor]]+Raw_Data[[#This Row],[Skor_Telat]] -> 8 | AI4: =IF(Raw_Data[[#This Row],[Risk_Score]]<=6,"Low Risk",IF(Raw_Data[[#This Row],[Risk_Score]]<=8,"Medium Risk","High Risk")) -> Medium Risk | AJ4: =IFERROR(DATEDIF(Raw_Data[[#This Row],[tanggal_pengajuan]],TODAY(),"m"),"N/A") -> 6 | AK4: =IF(ISNUMBER(Raw_Data[[#This Row],[MOB]]),IF(Raw_Data[[#This Row],[MOB]]<6,"0-5 bulan",IF(Raw_Data[[#This Row],[MOB]]<12,"6-11 bulan",IF(Raw_Data[[#This Row],[MOB]]<24,"12-23 bulan","24+ bulan"))),"N/A") -> 6-11 bulan
A5: KRM00004 | B5: 46080 | C5: =TEXT(B5,"mmmm") -> February | D5: Wahyu Nugroho | E5: 85921312898035 | F5: 51 | G5: Perempuan | H5: Karyawan Swasta | I5: 6295000 | J5: =Raw_Data[[#This Row],[cicilan_per_bulan]]/Raw_Data[[#This Row],[penghasilan_bulanan]] -> 0.22710087 | K5: Makassar | L5: Sulawesi Selatan | M5: Suzuki | N5: Address | O5: Matic Mid | P5: 21404000 | Q5: 6421000 | R5: =IF(Raw_Data[[#This Row],[persen_dp]]<15%,"Low",IF(Raw_Data[[#This Row],[persen_dp]]>25%,"High","Medium")) -> High | S5: 0.3 | T5: 12 | U5: 0.145 | V5: 1429600 | W5: 17156000 | X5: =IF(OR(Raw_Data[[#This Row],[status_pembayaran]]="Macet",Raw_Data[[#This Row],[status_pembayaran]]="Kurang Lancar"),"Non Performing Loan","Performing") -> Performing | Y5: Lancar | Z5: 0 | AA5: 0 | AB5: 1 | AC5: verifikasi | AD5: =IF(Raw_Data[[#This Row],[rasio]]<0.2,1,IF(Raw_Data[[#This Row],[rasio]]<0.3,2,IF(Raw_Data[[#This Row],[rasio]]<0.4,3,4))) -> 2 | AE5: =IF(Raw_Data[[#This Row],[kategori_dp]]="High",1,IF(Raw_Data[[#This Row],[kategori_dp]]="Medium",2,3)) -> 1 | AF5: =IF(Raw_Data[[#This Row],[tenor_bulan]]<=24,1,IF(Raw_Data[[#This Row],[tenor_bulan]]<=36,2,IF(Raw_Data[[#This Row],[tenor_bulan]]<=48,3,4))) -> 1 | AG5: =IF(Raw_Data[[#This Row],[jumlah_kali_telat]]=0,0,IF(Raw_Data[[#This Row],[jumlah_kali_telat]]<=2,2,4)) -> 0 | AH5: =Raw_Data[[#This Row],[Skor_Rasio]]+Raw_Data[[#This Row],[Skor_DP]]+Raw_Data[[#This Row],[Skor_Tenor]]+Raw_Data[[#This Row],[Skor_Telat]] -> 4 | AI5: =IF(Raw_Data[[#This Row],[Risk_Score]]<=6,"Low Risk",IF(Raw_Data[[#This Row],[Risk_Score]]<=8,"Medium Risk","High Risk")) -> Low Risk | AJ5: =IFERROR(DATEDIF(Raw_Data[[#This Row],[tanggal_pengajuan]],TODAY(),"m"),"N/A") -> 7 | AK5: =IF(ISNUMBER(Raw_Data[[#This Row],[MOB]]),IF(Raw_Data[[#This Row],[MOB]]<6,"0-5 bulan",IF(Raw_Data[[#This Row],[MOB]]<12,"6-11 bulan",IF(Raw_Data[[#This Row],[MOB]]<24,"12-23 bulan","24+ bulan"))),"N/A") -> 6-11 bulan
A6: KRM00005 | B6: 46087 | C6: =TEXT(B6,"mmmm") -> March | D6: Fajar Susanti | E6: 96512612807585 | F6: 48 | G6: Perempuan | H6: Wiraswasta | I6: 11254000 | J6: =Raw_Data[[#This Row],[cicilan_per_bulan]]/Raw_Data[[#This Row],[penghasilan_bulanan]] -> 0.045237249 | K6: Palembang | L6: Sumatera Selatan | M6: Honda | N6: Vario 125 | O6: Matic Mid | P6: 25299000 | Q6: 7590000 | R6: =IF(Raw_Data[[#This Row],[persen_dp]]<15%,"Low",IF(Raw_Data[[#This Row],[persen_dp]]>25%,"High","Medium")) -> High | S6: 0.3 | T6: 60 | U6: 0.145 | V6: 509100 | W6: 30549000 | X6: =IF(OR(Raw_Data[[#This Row],[status_pembayaran]]="Macet",Raw_Data[[#This Row],[status_pembayaran]]="Kurang Lancar"),"Non Performing Loan","Performing") -> Performing | Y6: Lancar | Z6: 0 | AA6: 0 | AB6: 1 | AC6: data kurang | AD6: =IF(Raw_Data[[#This Row],[rasio]]<0.2,1,IF(Raw_Data[[#This Row],[rasio]]<0.3,2,IF(Raw_Data[[#This Row],[rasio]]<0.4,3,4))) -> 1 | AE6: =IF(Raw_Data[[#This Row],[kategori_dp]]="High",1,IF(Raw_Data[[#This Row],[kategori_dp]]="Medium",2,3)) -> 1 | AF6: =IF(Raw_Data[[#This Row],[tenor_bulan]]<=24,1,IF(Raw_Data[[#This Row],[tenor_bulan]]<=36,2,IF(Raw_Data[[#This Row],[tenor_bulan]]<=48,3,4))) -> 4 | AG6: =IF(Raw_Data[[#This Row],[jumlah_kali_telat]]=0,0,IF(Raw_Data[[#This Row],[jumlah_kali_telat]]<=2,2,4)) -> 0 | AH6: =Raw_Data[[#This Row],[Skor_Rasio]]+Raw_Data[[#This Row],[Skor_DP]]+Raw_Data[[#This Row],[Skor_Tenor]]+Raw_Data[[#This Row],[Skor_Telat]] -> 6 | AI6: =IF(Raw_Data[[#This Row],[Risk_Score]]<=6,"Low Risk",IF(Raw_Data[[#This Row],[Risk_Score]]<=8,"Medium Risk","High Risk")) -> Low Risk | AJ6: =IFERROR(DATEDIF(Raw_Data[[#This Row],[tanggal_pengajuan]],TODAY(),"m"),"N/A") -> 7 | AK6: =IF(ISNUMBER(Raw_Data[[#This Row],[MOB]]),IF(Raw_Data[[#This Row],[MOB]]<6,"0-5 bulan",IF(Raw_Data[[#This Row],[MOB]]<12,"6-11 bulan",IF(Raw_Data[[#This Row],[MOB]]<24,"12-23 bulan","24+ bulan"))),"N/A") -> 6-11 bulan
A7: KRM00006 | B7: 46085 | C7: =TEXT(B7,"mmmm") -> March | D7: Bagus Wibowo | E7: 72882507851550 | F7: 39 | G7: Perempuan | H7: Ibu Rumah Tangga | I7: 3421000 | J7: =Raw_Data[[#This Row],[cicilan_per_bulan]]/Raw_Data[[#This Row],[penghasilan_bulanan]] -> 0.12984507 | K7: Banjarmasin | L7: Kalimantan Selatan | M7: Honda | N7: Beat Street | O7: Matic Entry | P7: 17994000 | Q7: 4499000 | R7: =IF(Raw_Data[[#This Row],[persen_dp]]<15%,"Low",IF(Raw_Data[[#This Row],[persen_dp]]>25%,"High","Medium")) -> Medium | S7: 0.25 | T7: 48 | U7: 0.145 | V7: 444200 | W7: 21322000 | X7: =IF(OR(Raw_Data[[#This Row],[status_pembayaran]]="Macet",Raw_Data[[#This Row],[status_pembayaran]]="Kurang Lancar"),"Non Performing Loan","Performing") -> Performing | Y7: Lancar | Z7: 0 | AA7: 0 | AB7: 1 | AD7: =IF(Raw_Data[[#This Row],[rasio]]<0.2,1,IF(Raw_Data[[#This Row],[rasio]]<0.3,2,IF(Raw_Data[[#This Row],[rasio]]<0.4,3,4))) -> 1 | AE7: =IF(Raw_Data[[#This Row],[kategori_dp]]="High",1,IF(Raw_Data[[#This Row],[kategori_dp]]="Medium",2,3)) -> 2 | AF7: =IF(Raw_Data[[#This Row],[tenor_bulan]]<=24,1,IF(Raw_Data[[#This Row],[tenor_bulan]]<=36,2,IF(Raw_Data[[#This Row],[tenor_bulan]]<=48,3,4))) -> 3 | AG7: =IF(Raw_Data[[#This Row],[jumlah_kali_telat]]=0,0,IF(Raw_Data[[#This Row],[jumlah_kali_telat]]<=2,2,4)) -> 0 | AH7: =Raw_Data[[#This Row],[Skor_Rasio]]+Raw_Data[[#This Row],[Skor_DP]]+Raw_Data[[#This Row],[Skor_Tenor]]+Raw_Data[[#This Row],[Skor_Telat]] -> 6 | AI7: =IF(Raw_Data[[#This Row],[Risk_Score]]<=6,"Low Risk",IF(Raw_Data[[#This Row],[Risk_Score]]<=8,"Medium Risk","High Risk")) -> Low Risk | AJ7: =IFERROR(DATEDIF(Raw_Data[[#This Row],[tanggal_pengajuan]],TODAY(),"m"),"N/A") -> 7 | AK7: =IF(ISNUMBER(Raw_Data[[#This Row],[MOB]]),IF(Raw_Data[[#This Row],[MOB]]<6,"0-5 bulan",IF(Raw_Data[[#This Row],[MOB]]<12,"6-11 bulan",IF(Raw_Data[[#This Row],[MOB]]<24,"12-23 bulan","24+ bulan"))),"N/A") -> 6-11 bulan
A8: KRM00007 | B8: 46145 | C8: =TEXT(B8,"mmmm") -> May | D8: Reza Saputra | E8: 61321304977738 | F8: 30 | G8: Lakilaki | H8: Karyawan Swasta | I8: 5406000 | J8: =Raw_Data[[#This Row],[cicilan_per_bulan]]/Raw_Data[[#This Row],[penghasilan_bulanan]] -> 0.26934887 | K8: Denpasar | L8: Bali | M8: Yamaha | N8: Lexi LX 155 | O8: Matic Mid | P8: 28704000 | Q8: 7176000 | R8: =IF(Raw_Data[[#This Row],[persen_dp]]<15%,"Low",IF(Raw_Data[[#This Row],[persen_dp]]>25%,"High","Medium")) -> Medium | S8: 0.25 | T8: 18 | U8: 0.145 | V8: 1456100 | W8: 26210000 | X8: =IF(OR(Raw_Data[[#This Row],[status_pembayaran]]="Macet",Raw_Data[[#This Row],[status_pembayaran]]="Kurang Lancar"),"Non Performing Loan","Performing") -> Performing | Y8: Lancar | Z8: 0 | AA8: 0 | AB8: 1 | AD8: =IF(Raw_Data[[#This Row],[rasio]]<0.2,1,IF(Raw_Data[[#This Row],[rasio]]<0.3,2,IF(Raw_Data[[#This Row],[rasio]]<0.4,3,4))) -> 2 | AE8: =IF(Raw_Data[[#This Row],[kategori_dp]]="High",1,IF(Raw_Data[[#This Row],[kategori_dp]]="Medium",2,3)) -> 2 | AF8: =IF(Raw_Data[[#This Row],[tenor_bulan]]<=24,1,IF(Raw_Data[[#This Row],[tenor_bulan]]<=36,2,IF(Raw_Data[[#This Row],[tenor_bulan]]<=48,3,4))) -> 1 | AG8: =IF(Raw_Data[[#This Row],[jumlah_kali_telat]]=0,0,IF(Raw_Data[[#This Row],[jumlah_kali_telat]]<=2,2,4)) -> 0 | AH8: =Raw_Data[[#This Row],[Skor_Rasio]]+Raw_Data[[#This Row],[Skor_DP]]+Raw_Data[[#This Row],[Skor_Tenor]]+Raw_Data[[#This Row],[Skor_Telat]] -> 5 | AI8: =IF(Raw_Data[[#This Row],[Risk_Score]]<=6,"Low Risk",IF(Raw_Data[[#This Row],[Risk_Score]]<=8,"Medium Risk","High Risk")) -> Low Risk | AJ8: =IFERROR(DATEDIF(Raw_Data[[#This Row],[tanggal_pengajuan]],TODAY(),"m"),"N/A") -> 5 | AK8: =IF(ISNUMBER(Raw_Data[[#This Row],[MOB]]),IF(Raw_Data[[#This Row],[MOB]]<6,"0-5 bulan",IF(Raw_Data[[#This Row],[MOB]]<12,"6-11 bulan",IF(Raw_Data[[#This Row],[MOB]]<24,"12-23 bulan","24+ bulan"))),"N/A") -> 0-5 bulan
A9: KRM00008 | B9: 46073 | C9: =TEXT(B9,"mmmm") -> February | D9: Tri Susanti | E9: 52992103506135 | F9: 58 | G9: Perempuan | H9: Freelancer | I9: 7661000 | J9: =Raw_Data[[#This Row],[cicilan_per_bulan]]/Raw_Data[[#This Row],[penghasilan_bulanan]] -> 0.16227647 | K9: Balikpapan | L9: Kalimantan Timur | M9: Honda | N9: Beat Street | O9: Matic Entry | P9: 18613000 | Q9: 5584000 | R9: =IF(Raw_Data[[#This Row],[persen_dp]]<15%,"Low",IF(Raw_Data[[#This Row],[persen_dp]]>25%,"High","Medium")) -> High | S9: 0.3 | T9: 12 | U9: 0.145 | V9: 1243200 | W9: 14918000 | X9: =IF(OR(Raw_Data[[#This Row],[status_pembayaran]]="Macet",Raw_Data[[#This Row],[status_pembayaran]]="Kurang Lancar"),"Non Performing Loan","Performing") -> Performing | Y9: Lancar | Z9: 0 | AA9: 0 | AB9: 1 | AD9: =IF(Raw_Data[[#This Row],[rasio]]<0.2,1,IF(Raw_Data[[#This Row],[rasio]]<0.3,2,IF(Raw_Data[[#This Row],[rasio]]<0.4,3,4))) -> 1 | AE9: =IF(Raw_Data[[#This Row],[kategori_dp]]="High",1,IF(Raw_Data[[#This Row],[kategori_dp]]="Medium",2,3)) -> 1 | AF9: =IF(Raw_Data[[#This Row],[tenor_bulan]]<=24,1,IF(Raw_Data[[#This Row],[tenor_bulan]]<=36,2,IF(Raw_Data[[#This Row],[tenor_bulan]]<=48,3,4))) -> 1 | AG9: =IF(Raw_Data[[#This Row],[jumlah_kali_telat]]=0,0,IF(Raw_Data[[#This Row],[jumlah_kali_telat]]<=2,2,4)) -> 0 | AH9: =Raw_Data[[#This Row],[Skor_Rasio]]+Raw_Data[[#This Row],[Skor_DP]]+Raw_Data[[#This Row],[Skor_Tenor]]+Raw_Data[[#This Row],[Skor_Telat]] -> 3 | AI9: =IF(Raw_Data[[#This Row],[Risk_Score]]<=6,"Low Risk",IF(Raw_Data[[#This Row],[Risk_Score]]<=8,"Medium Risk","High Risk")) -> Low Risk | AJ9: =IFERROR(DATEDIF(Raw_Data[[#This Row],[tanggal_pengajuan]],TODAY(),"m"),"N/A") -> 8 | AK9: =IF(ISNUMBER(Raw_Data[[#This Row],[MOB]]),IF(Raw_Data[[#This Row],[MOB]]<6,"0-5 bulan",IF(Raw_Data[[#This Row],[MOB]]<12,"6-11 bulan",IF(Raw_Data[[#This Row],[MOB]]<24,"12-23 bulan","24+ bulan"))),"N/A") -> 6-11 bulan
A10: KRM00009 | B10: 46152 | C10: =TEXT(B10,"mmmm") -> May | D10: Ahmad Pratama | E10: 95172805827750 | F10: 45 | G10: Lakilaki | H10: Tni/Polri | I10: 4894000 | J10: =Raw_Data[[#This Row],[cicilan_per_bulan]]/Raw_Data[[#This Row],[penghasilan_bulanan]] -> 0.071250511 | K10: Pekanbaru | L10: Riau | M10: Suzuki | N10: Nex II | O10: Matic Entry | P10: 16299000 | Q10: 5705000 | R10: =IF(Raw_Data[[#This Row],[persen_dp]]<15%,"Low",IF(Raw_Data[[#This Row],[persen_dp]]>25%,"High","Medium")) -> High | S10: 0.35 | T10: 48 | U10: 0.145 | V10: 348700 | W10: 16739000 | X10: =IF(OR(Raw_Data[[#This Row],[status_pembayaran]]="Macet",Raw_Data[[#This Row],[status_pembayaran]]="Kurang Lancar"),"Non Performing Loan","Performing") -> Performing | Y10: Lancar | Z10: 0 | AA10: 0 | AB10: 1 | AC10: ok | AD10: =IF(Raw_Data[[#This Row],[rasio]]<0.2,1,IF(Raw_Data[[#This Row],[rasio]]<0.3,2,IF(Raw_Data[[#This Row],[rasio]]<0.4,3,4))) -> 1 | AE10: =IF(Raw_Data[[#This Row],[kategori_dp]]="High",1,IF(Raw_Data[[#This Row],[kategori_dp]]="Medium",2,3)) -> 1 | AF10: =IF(Raw_Data[[#This Row],[tenor_bulan]]<=24,1,IF(Raw_Data[[#This Row],[tenor_bulan]]<=36,2,IF(Raw_Data[[#This Row],[tenor_bulan]]<=48,3,4))) -> 3 | AG10: =IF(Raw_Data[[#This Row],[jumlah_kali_telat]]=0,0,IF(Raw_Data[[#This Row],[jumlah_kali_telat]]<=2,2,4)) -> 0 | AH10: =Raw_Data[[#This Row],[Skor_Rasio]]+Raw_Data[[#This Row],[Skor_DP]]+Raw_Data[[#This Row],[Skor_Tenor]]+Raw_Data[[#This Row],[Skor_Telat]] -> 5 | AI10: =IF(Raw_Data[[#This Row],[Risk_Score]]<=6,"Low Risk",IF(Raw_Data[[#This Row],[Risk_Score]]<=8,"Medium Risk","High Risk")) -> Low Risk | AJ10: =IFERROR(DATEDIF(Raw_Data[[#This Row],[tanggal_pengajuan]],TODAY(),"m"),"N/A") -> 5 | AK10: =IF(ISNUMBER(Raw_Data[[#This Row],[MOB]]),IF(Raw_Data[[#This Row],[MOB]]<6,"0-5 bulan",IF(Raw_Data[[#This Row],[MOB]]<12,"6-11 bulan",IF(Raw_Data[[#This Row],[MOB]]<24,"12-23 bulan","24+ bulan"))),"N/A") -> 0-5 bulan
A11: KRM00010 | B11: 46111 | C11: =TEXT(B11,"mmmm") -> March | D11: Budi Santoso | E11: 72812506935975 | F11: 49 | G11: Lakilaki | H11: Driver Online | I11: 4753000 | J11: =Raw_Data[[#This Row],[cicilan_per_bulan]]/Raw_Data[[#This Row],[penghasilan_bulanan]] -> 0.23324216 | K11: Yogyakarta | L11: DIY | M11: Honda | N11: Beat Street | O11: Matic Entry | P11: 19364000 | Q11: 7746000 | R11: =IF(Raw_Data[[#This Row],[persen_dp]]<15%,"Low",IF(Raw_Data[[#This Row],[persen_dp]]>25%,"High","Medium")) -> High | S11: 0.4 | T11: 12 | U11: 0.145 | V11: 1108600 | W11: 13303000 | X11: =IF(OR(Raw_Data[[#This Row],[status_pembayaran]]="Macet",Raw_Data[[#This Row],[status_pembayaran]]="Kurang Lancar"),"Non Performing Loan","Performing") -> Performing | Y11: Lancar | Z11: 0 | AA11: 0 | AB11: 1 | AC11: approved | AD11: =IF(Raw_Data[[#This Row],[rasio]]<0.2,1,IF(Raw_Data[[#This Row],[rasio]]<0.3,2,IF(Raw_Data[[#This Row],[rasio]]<0.4,3,4))) -> 2 | AE11: =IF(Raw_Data[[#This Row],[kategori_dp]]="High",1,IF(Raw_Data[[#This Row],[kategori_dp]]="Medium",2,3)) -> 1 | AF11: =IF(Raw_Data[[#This Row],[tenor_bulan]]<=24,1,IF(Raw_Data[[#This Row],[tenor_bulan]]<=36,2,IF(Raw_Data[[#This Row],[tenor_bulan]]<=48,3,4))) -> 1 | AG11: =IF(Raw_Data[[#This Row],[jumlah_kali_telat]]=0,0,IF(Raw_Data[[#This Row],[jumlah_kali_telat]]<=2,2,4)) -> 0 | AH11: =Raw_Data[[#This Row],[Skor_Rasio]]+Raw_Data[[#This Row],[Skor_DP]]+Raw_Data[[#This Row],[Skor_Tenor]]+Raw_Data[[#This Row],[Skor_Telat]] -> 4 | AI11: =IF(Raw_Data[[#This Row],[Risk_Score]]<=6,"Low Risk",IF(Raw_Data[[#This Row],[Risk_Score]]<=8,"Medium Risk","High Risk")) -> Low Risk | AJ11: =IFERROR(DATEDIF(Raw_Data[[#This Row],[tanggal_pengajuan]],TODAY(),"m"),"N/A") -> 6 | AK11: =IF(ISNUMBER(Raw_Data[[#This Row],[MOB]]),IF(Raw_Data[[#This Row],[MOB]]<6,"0-5 bulan",IF(Raw_Data[[#This Row],[MOB]]<12,"6-11 bulan",IF(Raw_Data[[#This Row],[MOB]]<24,"12-23 bulan","24+ bulan"))),"N/A") -> 6-11 bulan
A12: KRM00011 | B12: 46134 | C12: =TEXT(B12,"mmmm") -> April | D12: Maya Anggraini | E12: 89231209751559 | F12: 33 | G12: Lakilaki | H12: Pns | I12: 4462000 | J12: =Raw_Data[[#This Row],[cicilan_per_bulan]]/Raw_Data[[#This Row],[penghasilan_bulanan]] -> 0.1783281 | K12: Depok | L12: Jawa Barat | M12: Yamaha | N12: Lexi LX 155 | O12: Matic Mid | P12: 28440000 | Q12: 4266000 | R12: =IF(Raw_Data[[#This Row],[persen_dp]]<15%,"Low",IF(Raw_Data[[#This Row],[persen_dp]]>25%,"High","Medium")) -> Medium | S12: 0.15 | T12: 48 | U12: 0.145 | V12: 795700 | W12: 38196000 | X12: =IF(OR(Raw_Data[[#This Row],[status_pembayaran]]="Macet",Raw_Data[[#This Row],[status_pembayaran]]="Kurang Lancar"),"Non Performing Loan","Performing") -> Performing | Y12: Lancar | Z12: 0 | AA12: 0 | AB12: 1 | AD12: =IF(Raw_Data[[#This Row],[rasio]]<0.2,1,IF(Raw_Data[[#This Row],[rasio]]<0.3,2,IF(Raw_Data[[#This Row],[rasio]]<0.4,3,4))) -> 1 | AE12: =IF(Raw_Data[[#This Row],[kategori_dp]]="High",1,IF(Raw_Data[[#This Row],[kategori_dp]]="Medium",2,3)) -> 2 | AF12: =IF(Raw_Data[[#This Row],[tenor_bulan]]<=24,1,IF(Raw_Data[[#This Row],[tenor_bulan]]<=36,2,IF(Raw_Data[[#This Row],[tenor_bulan]]<=48,3,4))) -> 3 | AG12: =IF(Raw_Data[[#This Row],[jumlah_kali_telat]]=0,0,IF(Raw_Data[[#This Row],[jumlah_kali_telat]]<=2,2,4)) -> 0 | AH12: =Raw_Data[[#This Row],[Skor_Rasio]]+Raw_Data[[#This Row],[Skor_DP]]+Raw_Data[[#This Row],[Skor_Tenor]]+Raw_Data[[#This Row],[Skor_Telat]] -> 6 | AI12: =IF(Raw_Data[[#This Row],[Risk_Score]]<=6,"Low Risk",IF(Raw_Data[[#This Row],[Risk_Score]]<=8,"Medium Risk","High Risk")) -> Low Risk | AJ12: =IFERROR(DATEDIF(Raw_Data[[#This Row],[tanggal_pengajuan]],TODAY(),"m"),"N/A") -> 6 | AK12: =IF(ISNUMBER(Raw_Data[[#This Row],[MOB]]),IF(Raw_Data[[#This Row],[MOB]]<6,"0-5 bulan",IF(Raw_Data[[#This Row],[MOB]]<12,"6-11 bulan",IF(Raw_Data[[#This Row],[MOB]]<24,"12-23 bulan","24+ bulan"))),"N/A") -> 6-11 bulan
A13: KRM00012 | B13: 46056 | C13: =TEXT(B13,"mmmm") -> February | D13: Reza Nugroho | E13: 42281511617389 | F13: 38 | G13: Perempuan | H13: Wiraswasta | I13: 9064000 | J13: =Raw_Data[[#This Row],[cicilan_per_bulan]]/Raw_Data[[#This Row],[penghasilan_bulanan]] -> 0.083086937 | K13: Tangerang | L13: Banten | M13: Yamaha | N13: Lexi LX 155 | O13: Matic Mid | P13: 29105000 | Q13: 2910000 | R13: =IF(Raw_Data[[#This Row],[persen_dp]]<15%,"Low",IF(Raw_Data[[#This Row],[persen_dp]]>25%,"High","Medium")) -> Low | S13: 0.1 | T13: 60 | U13: 0.145 | V13: 753100 | W13: 45186000 | X13: =IF(OR(Raw_Data[[#This Row],[status_pembayaran]]="Macet",Raw_Data[[#This Row],[status_pembayaran]]="Kurang Lancar"),"Non Performing Loan","Performing") -> Performing | Y13: Lancar | Z13: 0 | AA13: 0 | AB13: 1 | AD13: =IF(Raw_Data[[#This Row],[rasio]]<0.2,1,IF(Raw_Data[[#This Row],[rasio]]<0.3,2,IF(Raw_Data[[#This Row],[rasio]]<0.4,3,4))) -> 1 | AE13: =IF(Raw_Data[[#This Row],[kategori_dp]]="High",1,IF(Raw_Data[[#This Row],[kategori_dp]]="Medium",2,3)) -> 3 | AF13: =IF(Raw_Data[[#This Row],[tenor_bulan]]<=24,1,IF(Raw_Data[[#This Row],[tenor_bulan]]<=36,2,IF(Raw_Data[[#This Row],[tenor_bulan]]<=48,3,4))) -> 4 | AG13: =IF(Raw_Data[[#This Row],[jumlah_kali_telat]]=0,0,IF(Raw_Data[[#This Row],[jumlah_kali_telat]]<=2,2,4)) -> 0 | AH13: =Raw_Data[[#This Row],[Skor_Rasio]]+Raw_Data[[#This Row],[Skor_DP]]+Raw_Data[[#This Row],[Skor_Tenor]]+Raw_Data[[#This Row],[Skor_Telat]] -> 8 | AI13: =IF(Raw_Data[[#This Row],[Risk_Score]]<=6,"Low Risk",IF(Raw_Data[[#This Row],[Risk_Score]]<=8,"Medium Risk","High Risk")) -> Medium Risk | AJ13: =IFERROR(DATEDIF(Raw_Data[[#This Row],[tanggal_pengajuan]],TODAY(),"m"),"N/A") -> 8 | AK13: =IF(ISNUMBER(Raw_Data[[#This Row],[MOB]]),IF(Raw_Data[[#This Row],[MOB]]<6,"0-5 bulan",IF(Raw_Data[[#This Row],[MOB]]<12,"6-11 bulan",IF(Raw_Data[[#This Row],[MOB]]<24,"12-23 bulan","24+ bulan"))),"N/A") -> 6-11 bulan
A14: KRM00013 | B14: 46129 | C14: =TEXT(B14,"mmmm") -> April | D14: Fitriani Saputra | E14: 67421309835486 | F14: 27 | G14: Lakilaki | H14: Pns | I14: 4524000 | J14: =Raw_Data[[#This Row],[cicilan_per_bulan]]/Raw_Data[[#This Row],[penghasilan_bulanan]] -> 0.23328912 | K14: Semarang | L14: Jawa Tengah | M14: Yamaha | N14: NMAX 155 | O14: Matic Premium | P14: 35301000 | Q14: 8825000 | R14: =IF(Raw_Data[[#This Row],[persen_dp]]<15%,"Low",IF(Raw_Data[[#This Row],[persen_dp]]>25%,"High","Medium")) -> Medium | S14: 0.25 | T14: 36 | U14: 0.145 | V14: 1055400 | W14: 37993000 | X14: =IF(OR(Raw_Data[[#This Row],[status_pembayaran]]="Macet",Raw_Data[[#This Row],[status_pembayaran]]="Kurang Lancar"),"Non Performing Loan","Performing") -> Performing | Y14: Lancar | Z14: 0 | AA14: 0 | AB14: 1 | AD14: =IF(Raw_Data[[#This Row],[rasio]]<0.2,1,IF(Raw_Data[[#This Row],[rasio]]<0.3,2,IF(Raw_Data[[#This Row],[rasio]]<0.4,3,4))) -> 2 | AE14: =IF(Raw_Data[[#This Row],[kategori_dp]]="High",1,IF(Raw_Data[[#This Row],[kategori_dp]]="Medium",2,3)) -> 2 | AF14: =IF(Raw_Data[[#This Row],[tenor_bulan]]<=24,1,IF(Raw_Data[[#This Row],[tenor_bulan]]<=36,2,IF(Raw_Data[[#This Row],[tenor_bulan]]<=48,3,4))) -> 2 | AG14: =IF(Raw_Data[[#This Row],[jumlah_kali_telat]]=0,0,IF(Raw_Data[[#This Row],[jumlah_kali_telat]]<=2,2,4)) -> 0 | AH14: =Raw_Data[[#This Row],[Skor_Rasio]]+Raw_Data[[#This Row],[Skor_DP]]+Raw_Data[[#This Row],[Skor_Tenor]]+Raw_Data[[#This Row],[Skor_Telat]] -> 6 | AI14: =IF(Raw_Data[[#This Row],[Risk_Score]]<=6,"Low Risk",IF(Raw_Data[[#This Row],[Risk_Score]]<=8,"Medium Risk","High Risk")) -> Low Risk | AJ14: =IFERROR(DATEDIF(Raw_Data[[#This Row],[tanggal_pengajuan]],TODAY(),"m"),"N/A") -> 6 | AK14: =IF(ISNUMBER(Raw_Data[[#This Row],[MOB]]),IF(Raw_Data[[#This Row],[MOB]]<6,"0-5 bulan",IF(Raw_Data[[#This Row],[MOB]]<12,"6-11 bulan",IF(Raw_Data[[#This Row],[MOB]]<24,"12-23 bulan","24+ bulan"))),"N/A") -> 6-11 bulan
A15: KRM00014 | B15: 46029 | C15: =TEXT(B15,"mmmm") -> January | D15: Rahmat Anggraini | E15: 77882704575595 | F15: 56 | G15: Lakilaki | H15: Petani | I15: 3020000 | J15: =Raw_Data[[#This Row],[cicilan_per_bulan]]/Raw_Data[[#This Row],[penghasilan_bulanan]] -> 0.19781457 | K15: Malang | L15: Jawa Timur | M15: Honda | N15: Scoopy | O15: Matic Stylish | P15: 24447000 | Q15: 3667000 | R15: =IF(Raw_Data[[#This Row],[persen_dp]]<15%,"Low",IF(Raw_Data[[#This Row],[persen_dp]]>25%,"High","Medium")) -> Medium | S15: 0.15 | T15: 60 | U15: 0.145 | V15: 597400 | W15: 35845000 | X15: =IF(OR(Raw_Data[[#This Row],[status_pembayaran]]="Macet",Raw_Data[[#This Row],[status_pembayaran]]="Kurang Lancar"),"Non Performing Loan","Performing") -> Performing | Y15: Lancar | Z15: 0 | AA15: 0 | AB15: 1 | AC15: data kurang | AD15: =IF(Raw_Data[[#This Row],[rasio]]<0.2,1,IF(Raw_Data[[#This Row],[rasio]]<0.3,2,IF(Raw_Data[[#This Row],[rasio]]<0.4,3,4))) -> 1 | AE15: =IF(Raw_Data[[#This Row],[kategori_dp]]="High",1,IF(Raw_Data[[#This Row],[kategori_dp]]="Medium",2,3)) -> 2 | AF15: =IF(Raw_Data[[#This Row],[tenor_bulan]]<=24,1,IF(Raw_Data[[#This Row],[tenor_bulan]]<=36,2,IF(Raw_Data[[#This Row],[tenor_bulan]]<=48,3,4))) -> 4 | AG15: =IF(Raw_Data[[#This Row],[jumlah_kali_telat]]=0,0,IF(Raw_Data[[#This Row],[jumlah_kali_telat]]<=2,2,4)) -> 0 | AH15: =Raw_Data[[#This Row],[Skor_Rasio]]+Raw_Data[[#This Row],[Skor_DP]]+Raw_Data[[#This Row],[Skor_Tenor]]+Raw_Data[[#This Row],[Skor_Telat]] -> 7 | AI15: =IF(Raw_Data[[#This Row],[Risk_Score]]<=6,"Low Risk",IF(Raw_Data[[#This Row],[Risk_Score]]<=8,"Medium Risk","High Risk")) -> Medium Risk | AJ15: =IFERROR(DATEDIF(Raw_Data[[#This Row],[tanggal_pengajuan]],TODAY(),"m"),"N/A") -> 9 | AK15: =IF(ISNUMBER(Raw_Data[[#This Row],[MOB]]),IF(Raw_Data[[#This Row],[MOB]]<6,"0-5 bulan",IF(Raw_Data[[#This Row],[MOB]]<12,"6-11 bulan",IF(Raw_Data[[#This Row],[MOB]]<24,"12-23 bulan","24+ bulan"))),"N/A") -> 6-11 bulan
A16: KRM00015 | B16: 46134 | C16: =TEXT(B16,"mmmm") -> April | D16: Tri Utami | E16: 90171511902741 | F16: 53 | G16: Perempuan | H16: Karyawan Swasta | I16: 4964000 | J16: =Raw_Data[[#This Row],[cicilan_per_bulan]]/Raw_Data[[#This Row],[penghasilan_bulanan]] -> 0.19806608 | K16: Balikpapan | L16: Kalimantan Timur | M16: Suzuki | N16: Address | O16: Matic Mid | P16: 20325000 | Q16: 2032000 | R16: =IF(Raw_Data[[#This Row],[persen_dp]]<15%,"Low",IF(Raw_Data[[#This Row],[persen_dp]]>25%,"High","Medium")) -> Low | S16: 0.1 | T16: 24 | U16: 0.145 | V16: 983200 | W16: 23598000 | X16: =IF(OR(Raw_Data[[#This Row],[status_pembayaran]]="Macet",Raw_Data[[#This Row],[status_pembayaran]]="Kurang Lancar"),"Non Performing Loan","Performing") -> Performing | Y16: Lancar | Z16: 0 | AA16: 0 | AB16: 1 | AD16: =IF(Raw_Data[[#This Row],[rasio]]<0.2,1,IF(Raw_Data[[#This Row],[rasio]]<0.3,2,IF(Raw_Data[[#This Row],[rasio]]<0.4,3,4))) -> 1 | AE16: =IF(Raw_Data[[#This Row],[kategori_dp]]="High",1,IF(Raw_Data[[#This Row],[kategori_dp]]="Medium",2,3)) -> 3 | AF16: =IF(Raw_Data[[#This Row],[tenor_bulan]]<=24,1,IF(Raw_Data[[#This Row],[tenor_bulan]]<=36,2,IF(Raw_Data[[#This Row],[tenor_bulan]]<=48,3,4))) -> 1 | AG16: =IF(Raw_Data[[#This Row],[jumlah_kali_telat]]=0,0,IF(Raw_Data[[#This Row],[jumlah_kali_telat]]<=2,2,4)) -> 0 | AH16: =Raw_Data[[#This Row],[Skor_Rasio]]+Raw_Data[[#This Row],[Skor_DP]]+Raw_Data[[#This Row],[Skor_Tenor]]+Raw_Data[[#This Row],[Skor_Telat]] -> 5 | AI16: =IF(Raw_Data[[#This Row],[Risk_Score]]<=6,"Low Risk",IF(Raw_Data[[#This Row],[Risk_Score]]<=8,"Medium Risk","High Risk")) -> Low Risk | AJ16: =IFERROR(DATEDIF(Raw_Data[[#This Row],[tanggal_pengajuan]],TODAY(),"m"),"N/A") -> 6 | AK16: =IF(ISNUMBER(Raw_Data[[#This Row],[MOB]]),IF(Raw_Data[[#This Row],[MOB]]<6,"0-5 bulan",IF(Raw_Data[[#This Row],[MOB]]<12,"6-11 bulan",IF(Raw_Data[[#This Row],[MOB]]<24,"12-23 bulan","24+ bulan"))),"N/A") -> 6-11 bulan
A17: KRM00016 | B17: 46128 | C17: =TEXT(B17,"mmmm") -> April | D17: Dian Hakim | E17: 32261102651376 | F17: 40 | G17: Lakilaki | H17: Wiraswasta | I17: 6500000 | J17: =Raw_Data[[#This Row],[cicilan_per_bulan]]/Raw_Data[[#This Row],[penghasilan_bulanan]] -> 0.24701538 | K17: Depok | L17: Jawa Barat | M17: Yamaha | N17: Mio M3 | O17: Matic Entry | P17: 18697000 | Q17: 1870000 | R17: =IF(Raw_Data[[#This Row],[persen_dp]]<15%,"Low",IF(Raw_Data[[#This Row],[persen_dp]]>25%,"High","Medium")) -> Low | S17: 0.1 | T17: 12 | U17: 0.145 | V17: 1605600 | W17: 19267000 | X17: =IF(OR(Raw_Data[[#This Row],[status_pembayaran]]="Macet",Raw_Data[[#This Row],[status_pembayaran]]="Kurang Lancar"),"Non Performing Loan","Performing") -> Performing | Y17: Lancar | Z17: 0 | AA17: 0 | AB17: 1 | AC17: survey ulang | AD17: =IF(Raw_Data[[#This Row],[rasio]]<0.2,1,IF(Raw_Data[[#This Row],[rasio]]<0.3,2,IF(Raw_Data[[#This Row],[rasio]]<0.4,3,4))) -> 2 | AE17: =IF(Raw_Data[[#This Row],[kategori_dp]]="High",1,IF(Raw_Data[[#This Row],[kategori_dp]]="Medium",2,3)) -> 3 | AF17: =IF(Raw_Data[[#This Row],[tenor_bulan]]<=24,1,IF(Raw_Data[[#This Row],[tenor_bulan]]<=36,2,IF(Raw_Data[[#This Row],[tenor_bulan]]<=48,3,4))) -> 1 | AG17: =IF(Raw_Data[[#This Row],[jumlah_kali_telat]]=0,0,IF(Raw_Data[[#This Row],[jumlah_kali_telat]]<=2,2,4)) -> 0 | AH17: =Raw_Data[[#This Row],[Skor_Rasio]]+Raw_Data[[#This Row],[Skor_DP]]+Raw_Data[[#This Row],[Skor_Tenor]]+Raw_Data[[#This Row],[Skor_Telat]] -> 6 | AI17: =IF(Raw_Data[[#This Row],[Risk_Score]]<=6,"Low Risk",IF(Raw_Data[[#This Row],[Risk_Score]]<=8,"Medium Risk","High Risk")) -> Low Risk | AJ17: =IFERROR(DATEDIF(Raw_Data[[#This Row],[tanggal_pengajuan]],TODAY(),"m"),"N/A") -> 6 | AK17: =IF(ISNUMBER(Raw_Data[[#This Row],[MOB]]),IF(Raw_Data[[#This Row],[MOB]]<6,"0-5 bulan",IF(Raw_Data[[#This Row],[MOB]]<12,"6-11 bulan",IF(Raw_Data[[#This Row],[MOB]]<24,"12-23 bulan","24+ bulan"))),"N/A") -> 6-11 bulan
A18: KRM00017 | B18: 46296 | C18: =TEXT(B18,"mmmm") -> October | D18: Nurul Prasetyo | E18: 68902311577130 | F18: 53 | G18: Perempuan | H18: Tni/Polri | I18: 6377000 | J18: =Raw_Data[[#This Row],[cicilan_per_bulan]]/Raw_Data[[#This Row],[penghasilan_bulanan]] -> 0.073310334 | K18: Banjarmasin | L18: Kalimantan Selatan | M18: Yamaha | N18: Freego | O18: Matic Mid | P18: 23229000 | Q18: 6969000 | R18: =IF(Raw_Data[[#This Row],[persen_dp]]<15%,"Low",IF(Raw_Data[[#This Row],[persen_dp]]>25%,"High","Medium")) -> High | S18: 0.3 | T18: 60 | U18: 0.145 | V18: 467500 | W18: 28048000 | X18: =IF(OR(Raw_Data[[#This Row],[status_pembayaran]]="Macet",Raw_Data[[#This Row],[status_pembayaran]]="Kurang Lancar"),"Non Performing Loan","Performing") -> Performing | Y18: Lancar | Z18: 0 | AA18: 0 | AB18: 1 | AC18: data kurang | AD18: =IF(Raw_Data[[#This Row],[rasio]]<0.2,1,IF(Raw_Data[[#This Row],[rasio]]<0.3,2,IF(Raw_Data[[#This Row],[rasio]]<0.4,3,4))) -> 1 | AE18: =IF(Raw_Data[[#This Row],[kategori_dp]]="High",1,IF(Raw_Data[[#This Row],[kategori_dp]]="Medium",2,3)) -> 1 | AF18: =IF(Raw_Data[[#This Row],[tenor_bulan]]<=24,1,IF(Raw_Data[[#This Row],[tenor_bulan]]<=36,2,IF(Raw_Data[[#This Row],[tenor_bulan]]<=48,3,4))) -> 4 | AG18: =IF(Raw_Data[[#This Row],[jumlah_kali_telat]]=0,0,IF(Raw_Data[[#This Row],[jumlah_kali_telat]]<=2,2,4)) -> 0 | AH18: =Raw_Data[[#This Row],[Skor_Rasio]]+Raw_Data[[#This Row],[Skor_DP]]+Raw_Data[[#This Row],[Skor_Tenor]]+Raw_Data[[#This Row],[Skor_Telat]] -> 6 | AI18: =IF(Raw_Data[[#This Row],[Risk_Score]]<=6,"Low Risk",IF(Raw_Data[[#This Row],[Risk_Score]]<=8,"Medium Risk","High Risk")) -> Low Risk | AJ18: =IFERROR(DATEDIF(Raw_Data[[#This Row],[tanggal_pengajuan]],TODAY(),"m"),"N/A") -> 0 | AK18: =IF(ISNUMBER(Raw_Data[[#This Row],[MOB]]),IF(Raw_Data[[#This Row],[MOB]]<6,"0-5 bulan",IF(Raw_Data[[#This Row],[MOB]]<12,"6-11 bulan",IF(Raw_Data[[#This Row],[MOB]]<24,"12-23 bulan","24+ bulan"))),"N/A") -> 0-5 bulan
A19: KRM00018 | B19: 46107 | C19: =TEXT(B19,"mmmm") -> March | D19: Agus Lestari | E19: 55322306871332 | F19: 55 | G19: Lakilaki | H19: Wiraswasta | I19: 13602000 | J19: =Raw_Data[[#This Row],[cicilan_per_bulan]]/Raw_Data[[#This Row],[penghasilan_bulanan]] -> 0.078856051 | K19: Medan | L19: Sumatera Utara | M19: Yamaha | N19: Aerox 155 | O19: Matic Sport | P19: 30700000 | Q19: 10745000 | R19: =IF(Raw_Data[[#This Row],[persen_dp]]<15%,"Low",IF(Raw_Data[[#This Row],[persen_dp]]>25%,"High","Medium")) -> High | S19: 0.35 | T19: 24 | U19: 0.145 | V19: 1072600 | W19: 25742000 | X19: =IF(OR(Raw_Data[[#This Row],[status_pembayaran]]="Macet",Raw_Data[[#This Row],[status_pembayaran]]="Kurang Lancar"),"Non Performing Loan","Performing") -> Performing | Y19: Lancar | Z19: 0 | AA19: 0 | AB19: 1 | AD19: =IF(Raw_Data[[#This Row],[rasio]]<0.2,1,IF(Raw_Data[[#This Row],[rasio]]<0.3,2,IF(Raw_Data[[#This Row],[rasio]]<0.4,3,4))) -> 1 | AE19: =IF(Raw_Data[[#This Row],[kategori_dp]]="High",1,IF(Raw_Data[[#This Row],[kategori_dp]]="Medium",2,3)) -> 1 | AF19: =IF(Raw_Data[[#This Row],[tenor_bulan]]<=24,1,IF(Raw_Data[[#This Row],[tenor_bulan]]<=36,2,IF(Raw_Data[[#This Row],[tenor_bulan]]<=48,3,4))) -> 1 | AG19: =IF(Raw_Data[[#This Row],[jumlah_kali_telat]]=0,0,IF(Raw_Data[[#This Row],[jumlah_kali_telat]]<=2,2,4)) -> 0 | AH19: =Raw_Data[[#This Row],[Skor_Rasio]]+Raw_Data[[#This Row],[Skor_DP]]+Raw_Data[[#This Row],[Skor_Tenor]]+Raw_Data[[#This Row],[Skor_Telat]] -> 3 | AI19: =IF(Raw_Data[[#This Row],[Risk_Score]]<=6,"Low Risk",IF(Raw_Data[[#This Row],[Risk_Score]]<=8,"Medium Risk","High Risk")) -> Low Risk | AJ19: =IFERROR(DATEDIF(Raw_Data[[#This Row],[tanggal_pengajuan]],TODAY(),"m"),"N/A") -> 6 | AK19: =IF(ISNUMBER(Raw_Data[[#This Row],[MOB]]),IF(Raw_Data[[#This Row],[MOB]]<6,"0-5 bulan",IF(Raw_Data[[#This Row],[MOB]]<12,"6-11 bulan",IF(Raw_Data[[#This Row],[MOB]]<24,"12-23 bulan","24+ bulan"))),"N/A") -> 6-11 bulan
A20: KRM00019 | B20: 46113 | C20: =TEXT(B20,"mmmm") -> April | D20: Fajar Santoso | E20: 65792803727804 | F20: 45 | G20: Lakilaki | H20: Buruh/Operator | I20: 2677000 | J20: =Raw_Data[[#This Row],[cicilan_per_bulan]]/Raw_Data[[#This Row],[penghasilan_bulanan]] -> 0.43115428 | K20: Jakarta Timur | L20: DKI Jakarta | M20: Honda | N20: Vario 125 | O20: Matic Mid | P20: 24378000 | Q20: 7313000 | R20: =IF(Raw_Data[[#This Row],[persen_dp]]<15%,"Low",IF(Raw_Data[[#This Row],[persen_dp]]>25%,"High","Medium")) -> High | S20: 0.3 | T20: 18 | U20: 0.145 | V20: 1154200 | W20: 20776000 | X20: =IF(OR(Raw_Data[[#This Row],[status_pembayaran]]="Macet",Raw_Data[[#This Row],[status_pembayaran]]="Kurang Lancar"),"Non Performing Loan","Performing") -> Performing | Y20: Lancar | Z20: 0 | AA20: 0 | AB20: 1 | AC20: ok | AD20: =IF(Raw_Data[[#This Row],[rasio]]<0.2,1,IF(Raw_Data[[#This Row],[rasio]]<0.3,2,IF(Raw_Data[[#This Row],[rasio]]<0.4,3,4))) -> 4 | AE20: =IF(Raw_Data[[#This Row],[kategori_dp]]="High",1,IF(Raw_Data[[#This Row],[kategori_dp]]="Medium",2,3)) -> 1 | AF20: =IF(Raw_Data[[#This Row],[tenor_bulan]]<=24,1,IF(Raw_Data[[#This Row],[tenor_bulan]]<=36,2,IF(Raw_Data[[#This Row],[tenor_bulan]]<=48,3,4))) -> 1 | AG20: =IF(Raw_Data[[#This Row],[jumlah_kali_telat]]=0,0,IF(Raw_Data[[#This Row],[jumlah_kali_telat]]<=2,2,4)) -> 0 | AH20: =Raw_Data[[#This Row],[Skor_Rasio]]+Raw_Data[[#This Row],[Skor_DP]]+Raw_Data[[#This Row],[Skor_Tenor]]+Raw_Data[[#This Row],[Skor_Telat]] -> 6 | AI20: =IF(Raw_Data[[#This Row],[Risk_Score]]<=6,"Low Risk",IF(Raw_Data[[#This Row],[Risk_Score]]<=8,"Medium Risk","High Risk")) -> Low Risk | AJ20: =IFERROR(DATEDIF(Raw_Data[[#This Row],[tanggal_pengajuan]],TODAY(),"m"),"N/A") -> 6 | AK20: =IF(ISNUMBER(Raw_Data[[#This Row],[MOB]]),IF(Raw_Data[[#This Row],[MOB]]<6,"0-5 bulan",IF(Raw_Data[[#This Row],[MOB]]<12,"6-11 bulan",IF(Raw_Data[[#This Row],[MOB]]<24,"12-23 bulan","24+ bulan"))),"N/A") -> 6-11 bulan
A21: KRM00020 | B21: 46161 | C21: =TEXT(B21,"mmmm") -> May | D21: Dian Pratama | E21: 49691001679866 | F21: 51 | G21: Perempuan | H21: Freelancer | I21: 5715000 | J21: =Raw_Data[[#This Row],[cicilan_per_bulan]]/Raw_Data[[#This Row],[penghasilan_bulanan]] -> 0.10460192 | K21: Depok | L21: Jawa Barat | M21: Honda | N21: CB150R | O21: Sport | P21: 31992000 | Q21: 11197000 | R21: =IF(Raw_Data[[#This Row],[persen_dp]]<15%,"Low",IF(Raw_Data[[#This Row],[persen_dp]]>25%,"High","Medium")) -> High | S21: 0.35 | T21: 60 | U21: 0.145 | V21: 597800 | W21: 35871000 | X21: =IF(OR(Raw_Data[[#This Row],[status_pembayaran]]="Macet",Raw_Data[[#This Row],[status_pembayaran]]="Kurang Lancar"),"Non Performing Loan","Performing") -> Performing | Y21: Lancar | Z21: 0 | AA21: 0 | AB21: 1 | AC21: survey ulang | AD21: =IF(Raw_Data[[#This Row],[rasio]]<0.2,1,IF(Raw_Data[[#This Row],[rasio]]<0.3,2,IF(Raw_Data[[#This Row],[rasio]]<0.4,3,4))) -> 1 | AE21: =IF(Raw_Data[[#This Row],[kategori_dp]]="High",1,IF(Raw_Data[[#This Row],[kategori_dp]]="Medium",2,3)) -> 1 | AF21: =IF(Raw_Data[[#This Row],[tenor_bulan]]<=24,1,IF(Raw_Data[[#This Row],[tenor_bulan]]<=36,2,IF(Raw_Data[[#This Row],[tenor_bulan]]<=48,3,4))) -> 4 | AG21: =IF(Raw_Data[[#This Row],[jumlah_kali_telat]]=0,0,IF(Raw_Data[[#This Row],[jumlah_kali_telat]]<=2,2,4)) -> 0 | AH21: =Raw_Data[[#This Row],[Skor_Rasio]]+Raw_Data[[#This Row],[Skor_DP]]+Raw_Data[[#This Row],[Skor_Tenor]]+Raw_Data[[#This Row],[Skor_Telat]] -> 6 | AI21: =IF(Raw_Data[[#This Row],[Risk_Score]]<=6,"Low Risk",IF(Raw_Data[[#This Row],[Risk_Score]]<=8,"Medium Risk","High Risk")) -> Low Risk | AJ21: =IFERROR(DATEDIF(Raw_Data[[#This Row],[tanggal_pengajuan]],TODAY(),"m"),"N/A") -> 5 | AK21: =IF(ISNUMBER(Raw_Data[[#This Row],[MOB]]),IF(Raw_Data[[#This Row],[MOB]]<6,"0-5 bulan",IF(Raw_Data[[#This Row],[MOB]]<12,"6-11 bulan",IF(Raw_Data[[#This Row],[MOB]]<24,"12-23 bulan","24+ bulan"))),"N/A") -> 0-5 bulan
A22: KRM00021 | B22: 46032 | C22: =TEXT(B22,"mmmm") -> January | D22: Fitriani Permata | E22: 58912612701921 | F22: 21 | G22: Perempuan | H22: Karyawan Swasta | I22: 4813000 | J22: =Raw_Data[[#This Row],[cicilan_per_bulan]]/Raw_Data[[#This Row],[penghasilan_bulanan]] -> 0.30340744 | K22: Pekanbaru | L22: Riau | M22: Honda | N22: Vario 160 | O22: Matic Mid | P22: 30843000 | Q22: 9253000 | R22: =IF(Raw_Data[[#This Row],[persen_dp]]<15%,"Low",IF(Raw_Data[[#This Row],[persen_dp]]>25%,"High","Medium")) -> High | S22: 0.3 | T22: 18 | U22: 0.145 | V22: 1460300 | W22: 26286000 | X22: =IF(OR(Raw_Data[[#This Row],[status_pembayaran]]="Macet",Raw_Data[[#This Row],[status_pembayaran]]="Kurang Lancar"),"Non Performing Loan","Performing") -> Performing | Y22: Lancar | Z22: 0 | AA22: 0 | AB22: 1 | AD22: =IF(Raw_Data[[#This Row],[rasio]]<0.2,1,IF(Raw_Data[[#This Row],[rasio]]<0.3,2,IF(Raw_Data[[#This Row],[rasio]]<0.4,3,4))) -> 3 | AE22: =IF(Raw_Data[[#This Row],[kategori_dp]]="High",1,IF(Raw_Data[[#This Row],[kategori_dp]]="Medium",2,3)) -> 1 | AF22: =IF(Raw_Data[[#This Row],[tenor_bulan]]<=24,1,IF(Raw_Data[[#This Row],[tenor_bulan]]<=36,2,IF(Raw_Data[[#This Row],[tenor_bulan]]<=48,3,4))) -> 1 | AG22: =IF(Raw_Data[[#This Row],[jumlah_kali_telat]]=0,0,IF(Raw_Data[[#This Row],[jumlah_kali_telat]]<=2,2,4)) -> 0 | AH22: =Raw_Data[[#This Row],[Skor_Rasio]]+Raw_Data[[#This Row],[Skor_DP]]+Raw_Data[[#This Row],[Skor_Tenor]]+Raw_Data[[#This Row],[Skor_Telat]] -> 5 | AI22: =IF(Raw_Data[[#This Row],[Risk_Score]]<=6,"Low Risk",IF(Raw_Data[[#This Row],[Risk_Score]]<=8,"Medium Risk","High Risk")) -> Low Risk | AJ22: =IFERROR(DATEDIF(Raw_Data[[#This Row],[tanggal_pengajuan]],TODAY(),"m"),"N/A") -> 9 | AK22: =IF(ISNUMBER(Raw_Data[[#This Row],[MOB]]),IF(Raw_Data[[#This Row],[MOB]]<6,"0-5 bulan",IF(Raw_Data[[#This Row],[MOB]]<12,"6-11 bulan",IF(Raw_Data[[#This Row],[MOB]]<24,"12-23 bulan","24+ bulan"))),"N/A") -> 6-11 bulan
A23: KRM00022 | B23: 46115 | C23: =TEXT(B23,"mmmm") -> April | D23: Nia Permata | E23: 59151606728524 | F23: 50 | G23: Perempuan | H23: Karyawan Swasta | I23: 7745000 | J23: =Raw_Data[[#This Row],[cicilan_per_bulan]]/Raw_Data[[#This Row],[penghasilan_bulanan]] -> 0.10622337 | K23: Bekasi | L23: Jawa Barat | M23: Honda | N23: CB150R | O23: Sport | P23: 31754000 | Q23: 11114000 | R23: =IF(Raw_Data[[#This Row],[persen_dp]]<15%,"Low",IF(Raw_Data[[#This Row],[persen_dp]]>25%,"High","Medium")) -> High | S23: 0.35 | T23: 36 | U23: 0.145 | V23: 822700 | W23: 29619000 | X23: =IF(OR(Raw_Data[[#This Row],[status_pembayaran]]="Macet",Raw_Data[[#This Row],[status_pembayaran]]="Kurang Lancar"),"Non Performing Loan","Performing") -> Performing | Y23: Lancar | Z23: 0 | AA23: 0 | AB23: 1 | AC23: data kurang | AD23: =IF(Raw_Data[[#This Row],[rasio]]<0.2,1,IF(Raw_Data[[#This Row],[rasio]]<0.3,2,IF(Raw_Data[[#This Row],[rasio]]<0.4,3,4))) -> 1 | AE23: =IF(Raw_Data[[#This Row],[kategori_dp]]="High",1,IF(Raw_Data[[#This Row],[kategori_dp]]="Medium",2,3)) -> 1 | AF23: =IF(Raw_Data[[#This Row],[tenor_bulan]]<=24,1,IF(Raw_Data[[#This Row],[tenor_bulan]]<=36,2,IF(Raw_Data[[#This Row],[tenor_bulan]]<=48,3,4))) -> 2 | AG23: =IF(Raw_Data[[#This Row],[jumlah_kali_telat]]=0,0,IF(Raw_Data[[#This Row],[jumlah_kali_telat]]<=2,2,4)) -> 0 | AH23: =Raw_Data[[#This Row],[Skor_Rasio]]+Raw_Data[[#This Row],[Skor_DP]]+Raw_Data[[#This Row],[Skor_Tenor]]+Raw_Data[[#This Row],[Skor_Telat]] -> 4 | AI23: =IF(Raw_Data[[#This Row],[Risk_Score]]<=6,"Low Risk",IF(Raw_Data[[#This Row],[Risk_Score]]<=8,"Medium Risk","High Risk")) -> Low Risk | AJ23: =IFERROR(DATEDIF(Raw_Data[[#This Row],[tanggal_pengajuan]],TODAY(),"m"),"N/A") -> 6 | AK23: =IF(ISNUMBER(Raw_Data[[#This Row],[MOB]]),IF(Raw_Data[[#This Row],[MOB]]<6,"0-5 bulan",IF(Raw_Data[[#This Row],[MOB]]<12,"6-11 bulan",IF(Raw_Data[[#This Row],[MOB]]<24,"12-23 bulan","24+ bulan"))),"N/A") -> 6-11 bulan
A24: KRM00023 | B24: 46156 | C24: =TEXT(B24,"mmmm") -> May | D24: Joko Fauzi | E24: 37891906845342 | F24: 29 | G24: Lakilaki | H24: Karyawan Swasta | I24: 5038000 | J24: =Raw_Data[[#This Row],[cicilan_per_bulan]]/Raw_Data[[#This Row],[penghasilan_bulanan]] -> 0.63277094 | K24: Medan | L24: Sumatera Utara | M24: Honda | N24: ADV 160 | O24: Adventure | P24: 41763000 | Q24: 8353000 | R24: =IF(Raw_Data[[#This Row],[persen_dp]]<15%,"Low",IF(Raw_Data[[#This Row],[persen_dp]]>25%,"High","Medium")) -> Medium | S24: 0.2 | T24: 12 | U24: 0.145 | V24: 3187900 | W24: 38255000 | X24: =IF(OR(Raw_Data[[#This Row],[status_pembayaran]]="Macet",Raw_Data[[#This Row],[status_pembayaran]]="Kurang Lancar"),"Non Performing Loan","Performing") -> Performing | Y24: Lancar | Z24: 0 | AA24: 0 | AB24: 1 | AC24: verifikasi | AD24: =IF(Raw_Data[[#This Row],[rasio]]<0.2,1,IF(Raw_Data[[#This Row],[rasio]]<0.3,2,IF(Raw_Data[[#This Row],[rasio]]<0.4,3,4))) -> 4 | AE24: =IF(Raw_Data[[#This Row],[kategori_dp]]="High",1,IF(Raw_Data[[#This Row],[kategori_dp]]="Medium",2,3)) -> 2 | AF24: =IF(Raw_Data[[#This Row],[tenor_bulan]]<=24,1,IF(Raw_Data[[#This Row],[tenor_bulan]]<=36,2,IF(Raw_Data[[#This Row],[tenor_bulan]]<=48,3,4))) -> 1 | AG24: =IF(Raw_Data[[#This Row],[jumlah_kali_telat]]=0,0,IF(Raw_Data[[#This Row],[jumlah_kali_telat]]<=2,2,4)) -> 0 | AH24: =Raw_Data[[#This Row],[Skor_Rasio]]+Raw_Data[[#This Row],[Skor_DP]]+Raw_Data[[#This Row],[Skor_Tenor]]+Raw_Data[[#This Row],[Skor_Telat]] -> 7 | AI24: =IF(Raw_Data[[#This Row],[Risk_Score]]<=6,"Low Risk",IF(Raw_Data[[#This Row],[Risk_Score]]<=8,"Medium Risk","High Risk")) -> Medium Risk | AJ24: =IFERROR(DATEDIF(Raw_Data[[#This Row],[tanggal_pengajuan]],TODAY(),"m"),"N/A") -> 5 | AK24: =IF(ISNUMBER(Raw_Data[[#This Row],[MOB]]),IF(Raw_Data[[#This Row],[MOB]]<6,"0-5 bulan",IF(Raw_Data[[#This Row],[MOB]]<12,"6-11 bulan",IF(Raw_Data[[#This Row],[MOB]]<24,"12-23 bulan","24+ bulan"))),"N/A") -> 0-5 bulan
A25: KRM00024 | B25: 46155 | C25: =TEXT(B25,"mmmm") -> May | D25: Fitriani Lestari | E25: 38001412746465 | F25: 56 | G25: Perempuan | H25: Guru/Dosen | I25: 6380000 | J25: =Raw_Data[[#This Row],[cicilan_per_bulan]]/Raw_Data[[#This Row],[penghasilan_bulanan]] -> 0.089169279 | K25: Jakarta Utara | L25: DKI Jakarta | M25: Suzuki | N25: Address | O25: Matic Mid | P25: 20388000 | Q25: 6116000 | R25: =IF(Raw_Data[[#This Row],[persen_dp]]<15%,"Low",IF(Raw_Data[[#This Row],[persen_dp]]>25%,"High","Medium")) -> High | S25: 0.3 | T25: 36 | U25: 0.145 | V25: 568900 | W25: 20480000 | X25: =IF(OR(Raw_Data[[#This Row],[status_pembayaran]]="Macet",Raw_Data[[#This Row],[status_pembayaran]]="Kurang Lancar"),"Non Performing Loan","Performing") -> Performing | Y25: Lancar | Z25: 0 | AA25: 0 | AB25: 1 | AD25: =IF(Raw_Data[[#This Row],[rasio]]<0.2,1,IF(Raw_Data[[#This Row],[rasio]]<0.3,2,IF(Raw_Data[[#This Row],[rasio]]<0.4,3,4))) -> 1 | AE25: =IF(Raw_Data[[#This Row],[kategori_dp]]="High",1,IF(Raw_Data[[#This Row],[kategori_dp]]="Medium",2,3)) -> 1 | AF25: =IF(Raw_Data[[#This Row],[tenor_bulan]]<=24,1,IF(Raw_Data[[#This Row],[tenor_bulan]]<=36,2,IF(Raw_Data[[#This Row],[tenor_bulan]]<=48,3,4))) -> 2 | AG25: =IF(Raw_Data[[#This Row],[jumlah_kali_telat]]=0,0,IF(Raw_Data[[#This Row],[jumlah_kali_telat]]<=2,2,4)) -> 0 | AH25: =Raw_Data[[#This Row],[Skor_Rasio]]+Raw_Data[[#This Row],[Skor_DP]]+Raw_Data[[#This Row],[Skor_Tenor]]+Raw_Data[[#This Row],[Skor_Telat]] -> 4 | AI25: =IF(Raw_Data[[#This Row],[Risk_Score]]<=6,"Low Risk",IF(Raw_Data[[#This Row],[Risk_Score]]<=8,"Medium Risk","High Risk")) -> Low Risk | AJ25: =IFERROR(DATEDIF(Raw_Data[[#This Row],[tanggal_pengajuan]],TODAY(),"m"),"N/A") -> 5 | AK25: =IF(ISNUMBER(Raw_Data[[#This Row],[MOB]]),IF(Raw_Data[[#This Row],[MOB]]<6,"0-5 bulan",IF(Raw_Data[[#This Row],[MOB]]<12,"6-11 bulan",IF(Raw_Data[[#This Row],[MOB]]<24,"12-23 bulan","24+ bulan"))),"N/A") -> 0-5 bulan
A26: KRM00025 | B26: 46161 | C26: =TEXT(B26,"mmmm") -> May | D26: Rina Hidayah | E26: 92191010918864 | F26: 48 | G26: Lakilaki | H26: Karyawan Swasta | I26: 5068000 | J26: =Raw_Data[[#This Row],[cicilan_per_bulan]]/Raw_Data[[#This Row],[penghasilan_bulanan]] -> 0.17794002 | K26: Tangerang | L26: Banten | M26: Suzuki | N26: Address | O26: Matic Mid | P26: 20971000 | Q26: 4194000 | R26: =IF(Raw_Data[[#This Row],[persen_dp]]<15%,"Low",IF(Raw_Data[[#This Row],[persen_dp]]>25%,"High","Medium")) -> Medium | S26: 0.2 | T26: 24 | U26: 0.145 | V26: 901800 | W26: 21642000 | X26: =IF(OR(Raw_Data[[#This Row],[status_pembayaran]]="Macet",Raw_Data[[#This Row],[status_pembayaran]]="Kurang Lancar"),"Non Performing Loan","Performing") -> Performing | Y26: Lancar | Z26: 0 | AA26: 0 | AB26: 1 | AD26: =IF(Raw_Data[[#This Row],[rasio]]<0.2,1,IF(Raw_Data[[#This Row],[rasio]]<0.3,2,IF(Raw_Data[[#This Row],[rasio]]<0.4,3,4))) -> 1 | AE26: =IF(Raw_Data[[#This Row],[kategori_dp]]="High",1,IF(Raw_Data[[#This Row],[kategori_dp]]="Medium",2,3)) -> 2 | AF26: =IF(Raw_Data[[#This Row],[tenor_bulan]]<=24,1,IF(Raw_Data[[#This Row],[tenor_bulan]]<=36,2,IF(Raw_Data[[#This Row],[tenor_bulan]]<=48,3,4))) -> 1 | AG26: =IF(Raw_Data[[#This Row],[jumlah_kali_telat]]=0,0,IF(Raw_Data[[#This Row],[jumlah_kali_telat]]<=2,2,4)) -> 0 | AH26: =Raw_Data[[#This Row],[Skor_Rasio]]+Raw_Data[[#This Row],[Skor_DP]]+Raw_Data[[#This Row],[Skor_Tenor]]+Raw_Data[[#This Row],[Skor_Telat]] -> 4 | AI26: =IF(Raw_Data[[#This Row],[Risk_Score]]<=6,"Low Risk",IF(Raw_Data[[#This Row],[Risk_Score]]<=8,"Medium Risk","High Risk")) -> Low Risk | AJ26: =IFERROR(DATEDIF(Raw_Data[[#This Row],[tanggal_pengajuan]],TODAY(),"m"),"N/A") -> 5 | AK26: =IF(ISNUMBER(Raw_Data[[#This Row],[MOB]]),IF(Raw_Data[[#This Row],[MOB]]<6,"0-5 bulan",IF(Raw_Data[[#This Row],[MOB]]<12,"6-11 bulan",IF(Raw_Data[[#This Row],[MOB]]<24,"12-23 bulan","24+ bulan"))),"N/A") -> 0-5 bulan
A27: KRM00026 | B27: 46187 | C27: =TEXT(B27,"mmmm") -> June | D27: Andi Utami | E27: 55791609595065 | F27: 29 | G27: Perempuan | H27: Ibu Rumah Tangga | I27: 1828000 | J27: =Raw_Data[[#This Row],[cicilan_per_bulan]]/Raw_Data[[#This Row],[penghasilan_bulanan]] -> 1.3090263 | K27: Bekasi | L27: Jawa Barat | M27: Honda | N27: PCX 160 | O27: Matic Premium | P27: 35826000 | Q27: 10748000 | R27: =IF(Raw_Data[[#This Row],[persen_dp]]<15%,"Low",IF(Raw_Data[[#This Row],[persen_dp]]>25%,"High","Medium")) -> High | S27: 0.3 | T27: 12 | U27: 0.145 | V27: 2392900 | W27: 28715000 | X27: =IF(OR(Raw_Data[[#This Row],[status_pembayaran]]="Macet",Raw_Data[[#This Row],[status_pembayaran]]="Kurang Lancar"),"Non Performing Loan","Performing") -> Performing | Y27: Lancar | Z27: 0 | AA27: 0 | AB27: 1 | AC27: approved | AD27: =IF(Raw_Data[[#This Row],[rasio]]<0.2,1,IF(Raw_Data[[#This Row],[rasio]]<0.3,2,IF(Raw_Data[[#This Row],[rasio]]<0.4,3,4))) -> 4 | AE27: =IF(Raw_Data[[#This Row],[kategori_dp]]="High",1,IF(Raw_Data[[#This Row],[kategori_dp]]="Medium",2,3)) -> 1 | AF27: =IF(Raw_Data[[#This Row],[tenor_bulan]]<=24,1,IF(Raw_Data[[#This Row],[tenor_bulan]]<=36,2,IF(Raw_Data[[#This Row],[tenor_bulan]]<=48,3,4))) -> 1 | AG27: =IF(Raw_Data[[#This Row],[jumlah_kali_telat]]=0,0,IF(Raw_Data[[#This Row],[jumlah_kali_telat]]<=2,2,4)) -> 0 | AH27: =Raw_Data[[#This Row],[Skor_Rasio]]+Raw_Data[[#This Row],[Skor_DP]]+Raw_Data[[#This Row],[Skor_Tenor]]+Raw_Data[[#This Row],[Skor_Telat]] -> 6 | AI27: =IF(Raw_Data[[#This Row],[Risk_Score]]<=6,"Low Risk",IF(Raw_Data[[#This Row],[Risk_Score]]<=8,"Medium Risk","High Risk")) -> Low Risk | AJ27: =IFERROR(DATEDIF(Raw_Data[[#This Row],[tanggal_pengajuan]],TODAY(),"m"),"N/A") -> 4 | AK27: =IF(ISNUMBER(Raw_Data[[#This Row],[MOB]]),IF(Raw_Data[[#This Row],[MOB]]<6,"0-5 bulan",IF(Raw_Data[[#This Row],[MOB]]<12,"6-11 bulan",IF(Raw_Data[[#This Row],[MOB]]<24,"12-23 bulan","24+ bulan"))),"N/A") -> 0-5 bulan
A28: KRM00027 | B28: 46188 | C28: =TEXT(B28,"mmmm") -> June | D28: Bagus Lestari | E28: 76512604728470 | F28: 58 | G28: Lakilaki | H28: Karyawan Swasta | I28: 5834000 | J28: =Raw_Data[[#This Row],[cicilan_per_bulan]]/Raw_Data[[#This Row],[penghasilan_bulanan]] -> 0.11640384 | K28: Jakarta Barat | L28: DKI Jakarta | M28: Honda | N28: Vario 125 | O28: Matic Mid | P28: 25790000 | Q28: 5158000 | R28: =IF(Raw_Data[[#This Row],[persen_dp]]<15%,"Low",IF(Raw_Data[[#This Row],[persen_dp]]>25%,"High","Medium")) -> Medium | S28: 0.2 | T28: 48 | U28: 0.145 | V28: 679100 | W28: 32599000 | X28: =IF(OR(Raw_Data[[#This Row],[status_pembayaran]]="Macet",Raw_Data[[#This Row],[status_pembayaran]]="Kurang Lancar"),"Non Performing Loan","Performing") -> Performing | Y28: Lancar | Z28: 0 | AA28: 0 | AB28: 1 | AD28: =IF(Raw_Data[[#This Row],[rasio]]<0.2,1,IF(Raw_Data[[#This Row],[rasio]]<0.3,2,IF(Raw_Data[[#This Row],[rasio]]<0.4,3,4))) -> 1 | AE28: =IF(Raw_Data[[#This Row],[kategori_dp]]="High",1,IF(Raw_Data[[#This Row],[kategori_dp]]="Medium",2,3)) -> 2 | AF28: =IF(Raw_Data[[#This Row],[tenor_bulan]]<=24,1,IF(Raw_Data[[#This Row],[tenor_bulan]]<=36,2,IF(Raw_Data[[#This Row],[tenor_bulan]]<=48,3,4))) -> 3 | AG28: =IF(Raw_Data[[#This Row],[jumlah_kali_telat]]=0,0,IF(Raw_Data[[#This Row],[jumlah_kali_telat]]<=2,2,4)) -> 0 | AH28: =Raw_Data[[#This Row],[Skor_Rasio]]+Raw_Data[[#This Row],[Skor_DP]]+Raw_Data[[#This Row],[Skor_Tenor]]+Raw_Data[[#This Row],[Skor_Telat]] -> 6 | AI28: =IF(Raw_Data[[#This Row],[Risk_Score]]<=6,"Low Risk",IF(Raw_Data[[#This Row],[Risk_Score]]<=8,"Medium Risk","High Risk")) -> Low Risk | AJ28: =IFERROR(DATEDIF(Raw_Data[[#This Row],[tanggal_pengajuan]],TODAY(),"m"),"N/A") -> 4 | AK28: =IF(ISNUMBER(Raw_Data[[#This Row],[MOB]]),IF(Raw_Data[[#This Row],[MOB]]<6,"0-5 bulan",IF(Raw_Data[[#This Row],[MOB]]<12,"6-11 bulan",IF(Raw_Data[[#This Row],[MOB]]<24,"12-23 bulan","24+ bulan"))),"N/A") -> 0-5 bulan
A29: KRM00028 | B29: 46066 | C29: =TEXT(B29,"mmmm") -> February | D29: Indah Setiawan | E29: 90292507703895 | F29: 33 | G29: Lakilaki | H29: Karyawan Swasta | I29: 5429000 | J29: =Raw_Data[[#This Row],[cicilan_per_bulan]]/Raw_Data[[#This Row],[penghasilan_bulanan]] -> 0.10944925 | K29: Surabaya | L29: Jawa Timur | M29: Honda | N29: Scoopy | O29: Matic Stylish | P29: 24315000 | Q29: 3647000 | R29: =IF(Raw_Data[[#This Row],[persen_dp]]<15%,"Low",IF(Raw_Data[[#This Row],[persen_dp]]>25%,"High","Medium")) -> Medium | S29: 0.15 | T29: 60 | U29: 0.145 | V29: 594200 | W29: 35652000 | X29: =IF(OR(Raw_Data[[#This Row],[status_pembayaran]]="Macet",Raw_Data[[#This Row],[status_pembayaran]]="Kurang Lancar"),"Non Performing Loan","Performing") -> Performing | Y29: Lancar | Z29: 0 | AA29: 0 | AB29: 1 | AC29: survey ulang | AD29: =IF(Raw_Data[[#This Row],[rasio]]<0.2,1,IF(Raw_Data[[#This Row],[rasio]]<0.3,2,IF(Raw_Data[[#This Row],[rasio]]<0.4,3,4))) -> 1 | AE29: =IF(Raw_Data[[#This Row],[kategori_dp]]="High",1,IF(Raw_Data[[#This Row],[kategori_dp]]="Medium",2,3)) -> 2 | AF29: =IF(Raw_Data[[#This Row],[tenor_bulan]]<=24,1,IF(Raw_Data[[#This Row],[tenor_bulan]]<=36,2,IF(Raw_Data[[#This Row],[tenor_bulan]]<=48,3,4))) -> 4 | AG29: =IF(Raw_Data[[#This Row],[jumlah_kali_telat]]=0,0,IF(Raw_Data[[#This Row],[jumlah_kali_telat]]<=2,2,4)) -> 0 | AH29: =Raw_Data[[#This Row],[Skor_Rasio]]+Raw_Data[[#This Row],[Skor_DP]]+Raw_Data[[#This Row],[Skor_Tenor]]+Raw_Data[[#This Row],[Skor_Telat]] -> 7 | AI29: =IF(Raw_Data[[#This Row],[Risk_Score]]<=6,"Low Risk",IF(Raw_Data[[#This Row],[Risk_Score]]<=8,"Medium Risk","High Risk")) -> Medium Risk | AJ29: =IFERROR(DATEDIF(Raw_Data[[#This Row],[tanggal_pengajuan]],TODAY(),"m"),"N/A") -> 8 | AK29: =IF(ISNUMBER(Raw_Data[[#This Row],[MOB]]),IF(Raw_Data[[#This Row],[MOB]]<6,"0-5 bulan",IF(Raw_Data[[#This Row],[MOB]]<12,"6-11 bulan",IF(Raw_Data[[#This Row],[MOB]]<24,"12-23 bulan","24+ bulan"))),"N/A") -> 6-11 bulan
A30: KRM00029 | B30: 46168 | C30: =TEXT(B30,"mmmm") -> May | D30: Dian Setiawan | E30: 99451306678281 | F30: 37 | G30: Perempuan | H30: Wiraswasta | I30: 7889000 | J30: =Raw_Data[[#This Row],[cicilan_per_bulan]]/Raw_Data[[#This Row],[penghasilan_bulanan]] -> 0.20311827 | K30: Pekanbaru | L30: Riau | M30: Yamaha | N30: Aerox 155 | O30: Matic Sport | P30: 31587000 | Q30: 7897000 | R30: =IF(Raw_Data[[#This Row],[persen_dp]]<15%,"Low",IF(Raw_Data[[#This Row],[persen_dp]]>25%,"High","Medium")) -> Medium | S30: 0.25 | T30: 18 | U30: 0.145 | V30: 1602400 | W30: 28843000 | X30: =IF(OR(Raw_Data[[#This Row],[status_pembayaran]]="Macet",Raw_Data[[#This Row],[status_pembayaran]]="Kurang Lancar"),"Non Performing Loan","Performing") -> Performing | Y30: Lancar | Z30: 0 | AA30: 0 | AB30: 1 | AC30: verifikasi | AD30: =IF(Raw_Data[[#This Row],[rasio]]<0.2,1,IF(Raw_Data[[#This Row],[rasio]]<0.3,2,IF(Raw_Data[[#This Row],[rasio]]<0.4,3,4))) -> 2 | AE30: =IF(Raw_Data[[#This Row],[kategori_dp]]="High",1,IF(Raw_Data[[#This Row],[kategori_dp]]="Medium",2,3)) -> 2 | AF30: =IF(Raw_Data[[#This Row],[tenor_bulan]]<=24,1,IF(Raw_Data[[#This Row],[tenor_bulan]]<=36,2,IF(Raw_Data[[#This Row],[tenor_bulan]]<=48,3,4))) -> 1 | AG30: =IF(Raw_Data[[#This Row],[jumlah_kali_telat]]=0,0,IF(Raw_Data[[#This Row],[jumlah_kali_telat]]<=2,2,4)) -> 0 | AH30: =Raw_Data[[#This Row],[Skor_Rasio]]+Raw_Data[[#This Row],[Skor_DP]]+Raw_Data[[#This Row],[Skor_Tenor]]+Raw_Data[[#This Row],[Skor_Telat]] -> 5 | AI30: =IF(Raw_Data[[#This Row],[Risk_Score]]<=6,"Low Risk",IF(Raw_Data[[#This Row],[Risk_Score]]<=8,"Medium Risk","High Risk")) -> Low Risk | AJ30: =IFERROR(DATEDIF(Raw_Data[[#This Row],[tanggal_pengajuan]],TODAY(),"m"),"N/A") -> 4 | AK30: =IF(ISNUMBER(Raw_Data[[#This Row],[MOB]]),IF(Raw_Data[[#This Row],[MOB]]<6,"0-5 bulan",IF(Raw_Data[[#This Row],[MOB]]<12,"6-11 bulan",IF(Raw_Data[[#This Row],[MOB]]<24,"12-23 bulan","24+ bulan"))),"N/A") -> 0-5 bulan
A31: KRM00030 | B31: 46170 | C31: =TEXT(B31,"mmmm") -> May | D31: Budi Susanti | E31: 89692011766518 | F31: 27 | G31: Lakilaki | H31: Buruh/Operator | I31: 3659000 | J31: =Raw_Data[[#This Row],[cicilan_per_bulan]]/Raw_Data[[#This Row],[penghasilan_bulanan]] -> 0.27704291 | K31: Balikpapan | L31: Kalimantan Timur | M31: Yamaha | N31: Freego | O31: Matic Mid | P31: 23575000 | Q31: 4715000 | R31: =IF(Raw_Data[[#This Row],[persen_dp]]<15%,"Low",IF(Raw_Data[[#This Row],[persen_dp]]>25%,"High","Medium")) -> Medium | S31: 0.2 | T31: 24 | U31: 0.145 | V31: 1013700 | W31: 24329000 | X31: =IF(OR(Raw_Data[[#This Row],[status_pembayaran]]="Macet",Raw_Data[[#This Row],[status_pembayaran]]="Kurang Lancar"),"Non Performing Loan","Performing") -> Performing | Y31: Lancar | Z31: 0 | AA31: 0 | AB31: 1 | AC31: ok | AD31: =IF(Raw_Data[[#This Row],[rasio]]<0.2,1,IF(Raw_Data[[#This Row],[rasio]]<0.3,2,IF(Raw_Data[[#This Row],[rasio]]<0.4,3,4))) -> 2 | AE31: =IF(Raw_Data[[#This Row],[kategori_dp]]="High",1,IF(Raw_Data[[#This Row],[kategori_dp]]="Medium",2,3)) -> 2 | AF31: =IF(Raw_Data[[#This Row],[tenor_bulan]]<=24,1,IF(Raw_Data[[#This Row],[tenor_bulan]]<=36,2,IF(Raw_Data[[#This Row],[tenor_bulan]]<=48,3,4))) -> 1 | AG31: =IF(Raw_Data[[#This Row],[jumlah_kali_telat]]=0,0,IF(Raw_Data[[#This Row],[jumlah_kali_telat]]<=2,2,4)) -> 0 | AH31: =Raw_Data[[#This Row],[Skor_Rasio]]+Raw_Data[[#This Row],[Skor_DP]]+Raw_Data[[#This Row],[Skor_Tenor]]+Raw_Data[[#This Row],[Skor_Telat]] -> 5 | AI31: =IF(Raw_Data[[#This Row],[Risk_Score]]<=6,"Low Risk",IF(Raw_Data[[#This Row],[Risk_Score]]<=8,"Medium Risk","High Risk")) -> Low Risk | AJ31: =IFERROR(DATEDIF(Raw_Data[[#This Row],[tanggal_pengajuan]],TODAY(),"m"),"N/A") -> 4 | AK31: =IF(ISNUMBER(Raw_Data[[#This Row],[MOB]]),IF(Raw_Data[[#This Row],[MOB]]<6,"0-5 bulan",IF(Raw_Data[[#This Row],[MOB]]<12,"6-11 bulan",IF(Raw_Data[[#This Row],[MOB]]<24,"12-23 bulan","24+ bulan"))),"N/A") -> 0-5 bulan
